<?xml version="1.0" encoding="utf-8"?>
<!-- This URDF was automatically created by SolidWorks to URDF Exporter! Originally created by Stephen Brawner (brawner@gmail.com) 
     Commit Version: 1.5.1-0-g916b5db  Build Version: 1.5.7152.31018
     For more information, please see http://wiki.ros.org/sw_urdf_exporter -->
<robot
  name="gripper_sim">
  <link
    name="base_link">
    <inertial>
      <origin
        xyz="0.041011 0.046793 0.075216"
        rpy="0 0 0" />
      <mass
        value="0.78663" />
      <inertia
        ixx="0.00092457"
        ixy="1.6963E-18"
        ixz="2.6544E-21"
        iyy="0.00046089"
        iyz="1.7536E-20"
        izz="0.0011861" />
    </inertial>
    <visual>
      <origin
        xyz="0 0 0"
        rpy="0 0 0" />
      <geometry>
        <mesh
          filename="package://gripper_sim/meshes/base_link.STL" />
      </geometry>
      <material
        name="">
        <color
          rgba="0.89804 0.91765 0.92941 1" />
      </material>
    </visual>
    <collision>
      <origin
        xyz="0 0 0"
        rpy="0 0 0" />
      <geometry>
        <mesh
          filename="package://gripper_sim/meshes/base_link.STL" />
      </geometry>
    </collision>
  </link>
  <link
    name="finger1_link">
    <inertial>
      <origin
        xyz="0.056976 0.015337 0.01676"
        rpy="0 0 0" />
      <mass
        value="0.0167" />
      <inertia
        ixx="1.7002E-06"
        ixy="-2.6215E-07"
        ixz="1.4659E-12"
        iyy="2.8213E-05"
        iyz="-1.4394E-13"
        izz="2.845E-05" />
    </inertial>
    <visual>
      <origin
        xyz="0 0 0"
        rpy="0 0 0" />
      <geometry>
        <mesh
          filename="package://gripper_sim/meshes/finger1_link.STL" />
      </geometry>
      <material
        name="">
        <color
          rgba="1 1 1 1" />
      </material>
    </visual>
    <collision>
      <origin
        xyz="0 0 0"
        rpy="0 0 0" />
      <geometry>
        <mesh
          filename="package://gripper_sim/meshes/finger1_link.STL" />
      </geometry>
    </collision>
  </link>
  <joint
    name="finger1_joint"
    type="continuous">
    <origin
      xyz="0.041011 -0.058456 0.12221"
      rpy="1.5708 -1.5708 0" />
    <parent
      link="base_link" />
    <child
      link="finger1_link" />
    <axis
      xyz="0 0 1" />
  </joint>
  <link
    name="finger2_link">
    <inertial>
      <origin
        xyz="0.052556 0.013896 -0.0074998"
        rpy="0 0 0" />
      <mass
        value="0.016641" />
      <inertia
        ixx="1.4331E-06"
        ixy="-1.1571E-06"
        ixz="-2.2794E-10"
        iyy="3.2566E-05"
        iyz="-2.3298E-11"
        izz="3.3375E-05" />
    </inertial>
    <visual>
      <origin
        xyz="0 0 0"
        rpy="0 0 0" />
      <geometry>
        <mesh
          filename="package://gripper_sim/meshes/finger2_link.STL" />
      </geometry>
      <material
        name="">
        <color
          rgba="1 1 1 1" />
      </material>
    </visual>
    <collision>
      <origin
        xyz="0 0 0"
        rpy="0 0 0" />
      <geometry>
        <mesh
          filename="package://gripper_sim/meshes/finger2_link.STL" />
      </geometry>
    </collision>
  </link>
  <joint
    name="finger2_joint"
    type="continuous">
    <origin
      xyz="0.041011 -0.067716 0.12221"
      rpy="1.5708 -1.5708 0" />
    <parent
      link="base_link" />
    <child
      link="finger2_link" />
    <axis
      xyz="0 0 1" />
  </joint>
</robot>
